Workbook

Sheet Instructions
A1: Worksheet definitions and DCE Instructions
A3: WORKBOOK TABS
A4: The "Tabs" listed below contain data used to develop the building estimates and in many cases are linked together. A description for each workbook (tab) is defined below:
A6: ADJUSTMENT (TAB) | B6: This will typically not change and is based on estimators experience, accuracy and availability of site information and previous experience.
A8: INPUT TAB: | B8: This tab allows the user to change parameters of the estimate. Any changes made will be reflected in various elements in the cost estimate.
A10: 1 | B10: Enter the year of the estimate.
A11: =A10+1 -> 2 | B11: Verify/change yearly escalation rates.
A12: =A11+1 -> 3 | B12: Verify/change waste density rate
A13: =A12+1 -> 4 | B13: Update exchange rate, US to AU.
A14: =A13+1 -> 5 | B14: Update ANSTO labor rates
A15: =A14+1 -> 6 | B15: Update ANSTO waste disposal rates.
A16: =A15+1 -> 7 | B16: Update equipment costs and quantities. Specify whether costs are US or AU dollars, cell D85. Specify cost year, cell E86.
A17: =A16+1 -> 8 | B17: Update consumable costs and quantities.
A18: =A17+1 -> 9 | B18: Review building specific data and modify as needed.
A19: =A18+1 -> 10 | B19: The base estimates are based on a crew size of 12. The crew size can modified for each building by changing the number of crews under the building specific inputs. A smaller building may a require a smaller crew size and vice versa. This will require estimators judgement.
A21: COMPARISON TAB: | B21: This tab is for "Information only". It compares the Cost Estimate prepared by CAA to the 2018 PT&C DCE.
A23: WBS SUMMARY TAB | B23: This tab contains the Work Breakdown Structure for each of the five areas into the 7 sections as requested by ANSTO.
A25: BUILDING TABS | B25: This is the build up of the building specific cost estimate. It includes the undistributed costs, such as staffing and equipment and material, and the activity costs. The activity costs are determined by the building square meters and the unit rates determined from previous estimates.
A26: 1 | B26: Review cells highlighted in green and adjust as necessary.
A27: 2 | B27: Insert building area
A28: 3 | B28: Insert project duration. This is not a calculated duration, it is estimator's judgement.
A29: 4 | B29: Insert length of asbestos pipe, if any.
A30: 5 | B30: Insert number of crews adjustment, see 10 above.
A32: SUMMARY 2026 $ TAB | B32: This is a breakdown of the averages obtained from CAA Cost estimating data from other estimates. It is updated into 2026 AUD. Protected worksheet and no action needed. This worksheet should not be altered or change in any way.
A34: HIDDEN TABS: | B34: There are a number of hidden tabs which have site specific data for other DCE prepared by the estimators. The data in these tabs are linked to the overall cost estimate. These are protected worksheets. These should not be altered or change in any way.
A37: HOW TO MAKE CHANGESS AND USE THE CAA WORKBOOK
B38: The five buildings in this workbook B17, 18, 54, 56, 70, and BXX (BXX is generic example for use and practice) are considered the “Master File”. The DCE for each of these buildings share the same data from the “adjustments” and “Input tab”. If you change any data in these tabs, it has the potential to impact one or more of the other buildings. For example hourly labor rates are defined in the input tab and are used to determine management cost for all five building in the master file. Changing hourly rate will change all five cost estimates. Listed below are methods you can use to prepare a DCE for a new structure or building.
A40: A. Adjust or change data in the "Master File" - B17, 18, 54, 56, & 70
B41: This approach will basically change the existing CAA DCE. ANSTO may chose to change generic global data such as labor rates. This will change the DC for each of the 5 building (6 if you include Building XX.)
A42: 1 | B42: Using the input tab as shown above, change parameters as needed. Again, it should be noted that changing data on the input tab in most cases will change the cost estimate for each of the five buildings originally estimated.
A43: 2 | B43: Change parameters on the "Building Tab" to reflect attributes of the structure as needed. Note: Changes in the building tab will only impact the ones applicable for the building selected and not the other structures.
A44: B. Prepare DCE for a 5 or 6 Structures at one time using the Master File as a template
B45: This approach is recommended and allows ANSTO to use the existing Master File building work sheets to update 5 (or six if using Building XX) DCEs at one time.
A46: 1 | B46: Select 5 (or 6) new structures for DCEs. Collect specific data for those structures..
A47: 2 | B47: Change the workbook building names in the Master File to reflect the structures you will be estimating and save it under a new unique file name. Do not change the CAA Master file since this will serve as a "template" future estimates.
A48: 3 | B48: Using the input tab (as shown above), change parameters as needed for each of the structure capturing unique attributes.. Again, it should be noted that changing data on the input tab in most cases will change the cost estimate for each of the structures being estimated.
A49: 4 | B49: Review and change parameters on the "Building Tab" as needed. Note: Changing data in a building tab will not impact other 4 or 5 building in the new master file.
A50: C. Using the Master File to add just one structure without impacting completed estimates of other structures.
B51: This approach should be used if you want to just update one structure as a stand alone DCE. The five buildings in this workbook B17, 18, 54, 56, & 70 are considered the “Master File”. The DCE for each of these buildings share the same data from the “adjustments” and “Input tab”. If you change any data in these tabs, it has the potential to impact one or more of the other buildings. For example hourly labor rates are defined in the input tab and are used to determine management cost for all five building in the master file. Changing hourly rate will change all five cost estimates. To prepare an independent DCE and not impact the master file, follow the steps below.
B52: How to add a new structure:
...

Sheet Adjustments
A1: Class of Structure | B1: Description | C1: Adjustment | D1: NOTE the adjustment factors, C2 - C4 should be adjusted based on estimator experience or experience gained from previously completed decommissioning projecs.
A2: B1 | B2: Lab/Rad | C2: 0.5
A3: C1 | B3: Industrial/Rad | C3: 0
A4: D1 | B4: Non-Indust/Rad | C4: -0.5
A5: D2 | B5: Non-Indust/Non-Rad | C5: -0.5
A6: NOTE: Class is extracted from the Project Time and Cost 2018 DCE
A8: Productivity Loss Factors | C8: Resp. | D8: Rad/ | F8: Protective
B9: Height | C9: Protection | D9: ALARA | F9: Clothing | H9: Breaks
B10: 0.15 | C10: 0.38 | D10: 0.15 | F10: 0.23 | H10: 0.0833
E11: Summary | G11: Summary
A12: All factors | B12: 0.15 | C12: 0.38 | D12: 0.15 | E12: =SUM(B12:D12) -> 0.68 | F12: 0.23 | G12: =(1+E12)*(1+F12) -> 2.0664 | H12: 0.0833 | I12: =G12*(1+H12) -> 2.2385311
A13: All except Height | C13: 0.38 | D13: 0.15 | E13: =SUM(B13:D13) -> 0.53 | F13: 0.23 | G13: =(1+E13)*(1+F13) -> 1.8819 | H13: 0.0833 | I13: =G13*(1+H13) -> 2.0386623
A14: PCs, Rad and Respirator only | C14: 0.38 | D14: 0.15 | E14: =SUM(B14:D14) -> 0.53 | F14: 0.23 | G14: =(1+E14)*(1+F14) -> 1.8819 | I14: =G14*(1+H14) -> 1.8819
A15: All except Resp. | B15: 0.15 | D15: 0.15 | E15: =SUM(B15:D15) -> 0.3 | F15: 0.23 | G15: =(1+E15)*(1+F15) -> 1.599 | H15: 0.0833 | I15: =G15*(1+H15) -> 1.7321967
A16: Height, PCs and Rad only | B16: 0.15 | D16: 0.15 | E16: =SUM(B16:D16) -> 0.3 | F16: 0.23 | G16: =(1+E16)*(1+F16) -> 1.599 | I16: =G16*(1+H16) -> 1.599
A17: PCs, Rad and Break only | D17: 0.15 | E17: =SUM(B17:D17) -> 0.15 | F17: 0.23 | G17: =(1+E17)*(1+F17) -> 1.4145 | H17: 0.0833 | I17: =G17*(1+H17) -> 1.5323278
A18: PCs and Rad only | D18: 0.15 | E18: =SUM(B18:D18) -> 0.15 | F18: 0.23 | G18: =(1+E18)*(1+F18) -> 1.4145 | I18: =G18*(1+H18) -> 1.4145
A19: Height and Breaks only | B19: 0.15 | E19: =SUM(B19:D19) -> 0.15 | G19: =(1+E19)*(1+F19) -> 1.15 | H19: 0.0833 | I19: =G19*(1+H19) -> 1.245795
A20: Height only | B20: 0.15 | E20: =SUM(B20:D20) -> 0.15 | G20: =(1+E20)*(1+F20) -> 1.15 | H20: 0 | I20: =G20*(1+H20) -> 1.15
A21: Breaks only | E21: =SUM(B21:D21) -> 0 | G21: =(1+E21)*(1+F21) -> 1 | H21: 0.0833 | I21: =G21*(1+H21) -> 1.0833
A23: NOTE: Source: AIF/NESP-036
A24: 1. The adjustment factors applies are the estimators judgement for a class 4 estimate. If this were a bottoms up estimate the below productivity loss factors would be applied on a line item basis.
A26: 2. The base estimate used to develop the ANSTO estimates are considered to be for facilities designated as C1. A designation of B1 would require an increase in costs, in this case a 50% increase. This increase falls within the adjustments identified in the PLF table.
A28: 3. Since the base estimates are considered for C1 buildings, D1 and D2 facilities would require less effort. Estimators judgement was used to arrive at these adjustment factors.

Sheet Inputs
A1: Items highlighted in green can be adjusted as needed.
A2: Year of Estimate: | B2: 2026 | C2: =LOOKUP(B$2,A6:A34,C6:C34) -> 1.6081076
B3: From | C3: =A6 -> 2008 | D3: =C3+1 -> 2009 | E3: =D3+1 -> 2010 | F3: =E3+1 -> 2011 | G3: =F3+1 -> 2012 | H3: =G3+1 -> 2013 | I3: =H3+1 -> 2014 | J3: =I3+1 -> 2015 | K3: =J3+1 -> 2016 | ... AD3: =AC3+1 -> 2035
A4: Escalation | B4: To | C4: =$B2 -> 2026 | D4: =$B2 -> 2026 | E4: =$B2 -> 2026 | F4: =$B2 -> 2026 | G4: =$B2 -> 2026 | H4: =$B2 -> 2026 | I4: =$B2 -> 2026 | J4: =$B2 -> 2026 | ... AD4: =$B2 -> 2026
C5: =IF($D6>0,$D6,"na") -> 0.60810763 | D5: =IF($D7>0,$D7,"na") -> 0.58013917 | E5: =IF($D8>0,$D8,"na") -> 0.53530817 | F5: =IF($D9>0,$D9,"na") -> 0.48626154 | G5: =IF($D10>0,$D10,"na") -> 0.46055576 | H5: =IF($D11>0,$D11,"na") -> 0.42562788 | I5: =IF($D12>0,$D12,"na") -> 0.39099217 | J5: =IF($D13>0,$D13,"na") -> 0.37030063 | K5: =IF($D14>0,$D14,"na") -> 0.35298246 | L5: =IF($D15>0,$D15,"na") -> 0.32710393 | M5: =IF($D16>0,$D16,"na") -> 0.30223131 | N5: =IF($D17>0,$D17,"na") -> 0.28159759 | O5: =IF($D18>0,$D18,"na") -> 0.27079583 | P5: =IF($D19>0,$D19,"na") -> 0.23546162 | Q5: =IF($D20>0,$D20,"na") -> 0.15907836 | R5: =IF($D21>0,$D21,"na") -> 0.097612084 | S5: =IF($D22>0,$D22,"na") -> 0.06399 | T5: =IF($D23>0,$D23,"na") -> 0.03 | U5: =IF($D24>0,$D24,"na") -> na | V5: =IF($D25>0,$D25,"na") -> na | W5: =IF($D26>0,$D26,"na") -> na | X5: =IF($D27>0,$D27,"na") -> na | Y5: =IF($D28>0,$D28,"na") -> na | Z5: =IF($D29>0,$D29,"na") -> na | AA5: =IF($D30>0,$D30,"na") -> na | AB5: =IF($D31>0,$D31,"na") -> na | AC5: =IF($D32>0,$D32,"na") -> na | AD5: =IF($D33>0,$D33,"na") -> na
A6: 2008 | B6: 1 | C6: =B6 -> 1 | D6: =(C$2-C6)/C6 -> 0.60810763
A7: =A6+1 -> 2009 | B7: 0.0177 | C7: =B6*(1+B7) -> 1.0177 | D7: =(C$2-C7)/C7 -> 0.58013917
A8: =A7+1 -> 2010 | B8: 0.0292 | C8: =C7*(1+B8) -> 1.0474168 | D8: =(C$2-C8)/C8 -> 0.53530817
A9: =A8+1 -> 2011 | B9: 0.033 | C9: =C8*(1+B9) -> 1.0819816 | D9: =(C$2-C9)/C9 -> 0.48626154
A10: =A9+1 -> 2012 | B10: 0.0176 | C10: =C9*(1+B10) -> 1.1010245 | D10: =(C$2-C10)/C10 -> 0.46055576
A11: =A10+1 -> 2013 | B11: 0.0245 | C11: =C10*(1+B11) -> 1.1279996 | D11: =(C$2-C11)/C11 -> 0.42562788
A12: =A11+1 -> 2014 | B12: 0.0249 | C12: =C11*(1+B12) -> 1.1560868 | D12: =(C$2-C12)/C12 -> 0.39099217
A13: =A12+1 -> 2015 | B13: 0.0151 | C13: =C12*(1+B13) -> 1.1735437 | D13: =(C$2-C13)/C13 -> 0.37030063
A14: =A13+1 -> 2016 | B14: 0.0128 | C14: =C13*(1+B14) -> 1.188565 | D14: =(C$2-C14)/C14 -> 0.35298246
A15: =A14+1 -> 2017 | B15: 0.0195 | C15: =C14*(1+B15) -> 1.211742 | D15: =(C$2-C15)/C15 -> 0.32710393
A16: =A15+1 -> 2018 | B16: 0.0191 | C16: =C15*(1+B16) -> 1.2348863 | D16: =(C$2-C16)/C16 -> 0.30223131
A17: =A16+1 -> 2019 | B17: 0.0161 | C17: =C16*(1+B17) -> 1.254768 | D17: =(C$2-C17)/C17 -> 0.28159759
A18: =A17+1 -> 2020 | B18: 0.0085 | C18: =C17*(1+B18) -> 1.2654335 | D18: =(C$2-C18)/C18 -> 0.27079583
A19: =A18+1 -> 2021 | B19: 0.0286 | C19: =C18*(1+B19) -> 1.3016249 | D19: =(C$2-C19)/C19 -> 0.23546162
... A24: =A23+1 -> 2026 | B24: 0.03 | C24: =C23*(1+B24) -> 1.6081076 | D24: =(C$2-C24)/C24 -> 0
A25: =A24+1 -> 2027 | B25: =AVERAGE(B$7:B$24) -> 0.026838889 | C25: =C24*(1+B25) -> 1.6512675 | D25: =(C$2-C25)/C25 -> -0.02613739
A26: =A25+1 -> 2028 | B26: =AVERAGE(B$7:B$24) -> 0.026838889 | C26: =C25*(1+B26) -> 1.6955856 | D26: =(C$2-C26)/C26 -> -0.051591618
A27: =A26+1 -> 2029 | B27: =AVERAGE(B$7:B$24) -> 0.026838889 | C27: =C26*(1+B27) -> 1.7410933 | D27: =(C$2-C27)/C27 -> -0.076380538
A28: =A27+1 -> 2030 | B28: =AVERAGE(B$7:B$24) -> 0.026838889 | C28: =C27*(1+B28) -> 1.7878223 | D28: =(C$2-C28)/C28 -> -0.10052154
A29: =A28+1 -> 2031 | B29: =AVERAGE(B$7:B$24) -> 0.026838889 | C29: =C28*(1+B29) -> 1.8358054 | D29: =(C$2-C29)/C29 -> -0.12403156
A30: =A29+1 -> 2032 | B30: =AVERAGE(B$7:B$24) -> 0.026838889 | C30: =C29*(1+B30) -> 1.8850764 | D30: =(C$2-C30)/C30 -> -0.14692709
A31: =A30+1 -> 2033 | B31: =AVERAGE(B$7:B$24) -> 0.026838889 | C31: =C30*(1+B31) -> 1.9356698 | D31: =(C$2-C31)/C31 -> -0.16922419
A32: =A31+1 -> 2034 | B32: =AVERAGE(B$7:B$24) -> 0.026838889 | C32: =C31*(1+B32) -> 1.987621 | D32: =(C$2-C32)/C32 -> -0.1909385
A33: =A32+1 -> 2035 | B33: =AVERAGE(B$7:B$24) -> 0.026838889 | C33: =C32*(1+B33) -> 2.0409665 | D33: =(C$2-C33)/C33 -> -0.21208526
A34: =A33+1 -> 2036 | B34: =AVERAGE(B$7:B$24) -> 0.026838889 | C34: =C33*(1+B34) -> 2.0957438 | D34: =(C$2-C34)/C34 -> -0.23267929
A36: Waste Density | B36: 100 | C36: lbs/cuft
A37: Exchange rate | B37: 45946.508 | C37: 1.54
B39: Rates | D39: Actuals | E39: Actuals | F39: +4.8% (3.4% EBA +1.4% Band Level) | G39: +4.8% (3.4% EBA +1.4% Band Level)
A40: ANSTO LABOR RATES | D40: Jul-Apr26 | E40: May-Jun26. +3.4%
B41: CLASS | C41: Band | D41: FY26 | F41: FY27 (Forecast) | G41: FY28
G42: (Forecast)
A43: Resource Type | B43: (SAP Name) | C43: (EA name) | D43: $/hour | E43: $/hour | F43: $/hour | G43: $/hour
B44: CLASS1 | C44: Band 1 | D44: 45.99 | E44: 47.55 | F44: 48.2 | G44: 50.51
B45: CLASS2 | C45: Band 2 | D45: 52.44 | E45: 54.22 | F45: 54.96 | G45: 57.6
B46: CLASS3 | C46: Band 3 | D46: 63.63 | E46: 65.79 | F46: 66.68 | G46: 69.88
...

Sheet Comparison
A1: COMPARISON OF ESTIMATES BETWEEN 2018 PT&C ESITMATE AND CAA ESTIMATE
A2: Facility Name/Description | B2: Gross Area (SM) | C2: Facility Class Adj | D2: Total Cost (FY18 AU$) | E2: Unit Cost (AU$/SM) | F2: Total Cost (FY26 AU$) | G2: Unit Cost (AU$/SM) | H2: CAA Estimate, 2026AU$ | I2: Delta
A3: B17A - Nuclear Services (Material Storage) | B3: =Inputs!G142 -> 158 | C3: =Inputs!C139 -> D1 | I3: Variance from PT&C and CAA
A4: B17B - Nuclear Operations (Workshop) | B4: =Inputs!F142 -> 704 | C4: =Inputs!F139 -> C1 | I4: Delta | J4: % | K4: Item
A5: B17 | B5: =SUM(B3:B4) -> 862 | D5: 1931756.7 | E5: =D5/B5 -> 2241.017 | F5: =(1+Inputs!$M$5)*Comparison!D5 -> 2515594.1 | G5: =F5/B5 -> 2918.3226 | H5: ='WBS Summary'!M27 -> 2665719.5 | I5: =H5-F5 -> 150125.43 | J5: =I5/F5 -> 0.059677925 | K5: B17
A6: B18 | C6: =Inputs!B150 -> D2 | D6: 3579999.2 | F6: =(1+Inputs!$M$5)*Comparison!D6 -> 4661987.1 | H6: ='WBS Summary'!M51 -> 5140902.6 | I6: =H6-F6 -> 478915.52 | J6: =I6/F6 -> 0.10272777 | K6: B18
A7: B54 | C7: =Inputs!B169 -> B1 | D7: 12388722 | F7: =(1+Inputs!$M$5)*Comparison!D7 -> 16132982 | H7: ='WBS Summary'!M78 -> 14159309 | I7: =H7-F7 -> -1973672.5 | J7: =I7/F7 -> -0.12233774 | K7: B54
A8: B56 | C8: =Inputs!B206 -> B1 | D8: 13866487 | F8: =(1+Inputs!$M$5)*Comparison!D8 -> 18057374 | H8: ='WBS Summary'!M104 -> 14150956 | I8: =H8-F8 -> -3906418 | J8: =I8/F8 -> -0.21633367 | K8: B56
A9: B70 | C9: =Inputs!B248 -> D2 | D9: 487422.3 | F9: =(1+Inputs!$M$5)*Comparison!D9 -> 634736.58 | H9: ='WBS Summary'!M133 -> 765186.91 | I9: =H9-F9 -> 130450.33 | J9: =I9/F9 -> 0.20551885 | K9: B70

Sheet WBS Summary
A2: ESTIMATED COSTS BY WORK BREAKDOWN STRUCTURE - B17, 18, 54 ,56 & 70
A4: WBS | B4: Description | C4: LSA Waste (M3) | D4: Hazardous Waste Vol (M3) | E4: Mixed Waste Vol (M3) | F4: Clean Waste Vol. (M3) | G4: Mat's, Consumables & Equip. | H4: Labor Cost | I4: LSA Waste Cost (TBD) | J4: Hazardous Waste Cost | K4: Mixed Waste Cost | L4: Clean Waste Cost | M4: Total Cost
A5: 1.0 | B5: Building B17
A6: 1.1 | B6: Project Management
A7: 1.1.1 | B7: Staff | H7: ='Building B17'!I14 -> 268756.2 | M7: =SUM(G7:L7) -> 268756.2
A8: 1.1.2 | B8: Equipment, Materials & Consumables | G8: ='Building B17'!S7 -> 649056.62 | M8: =SUM(G8:L8) -> 649056.62
A9: 1.2 | B9: Project Planning
A10: 1.2.1 | B10: Procedure Development | H10: ='Building B17'!T67 -> 22935.2 | M10: =SUM(G10:L10) -> 22935.2
A11: 1.2.2 | B11: QA and Safety Documents | H11: ='Building B17'!T74 -> 22935.2 | M11: =SUM(G11:L11) -> 22935.2
A12: 1.2.3 | B12: Mobilization | H12: ='Building B17'!T81 -> 123378.7 | M12: =SUM(G12:L12) -> 123378.7
A13: 1.3 | B13: Preliminary Site Investigation | M13: =SUM(G13:L13) -> 0
A14: 1.3.1 | B14: Decontamination Readiness Review | H14: See Note | M14: =SUM(G14:L14) -> 0
A15: 1.3.2 | B15: Site Prep | H15: ='Building B17'!T121 -> 45402.544 | M15: =SUM(G15:L15) -> 45402.544
A16: 1.4 | B16: Detailed Characterization | H16: ='Building B17'!T176 -> 74430.4 | M16: =SUM(G16:L16) -> 74430.4
A17: 1.5 | B17: Decontamination
A18: 1.5.1 | B18: Asbestos Removal | H18: 0 | M18: =SUM(G18:L18) -> 0
A19: 1.5.2 | B19: Remove systems and Components | H19: ='Building B17'!I196 -> 365585.28 | M19: =SUM(G19:L19) -> 365585.28
A20: 1.5.3 | B20: Decontaminate Structure | C20: =IF('Building B17'!N184>0,'Building B17'!N184, " ") -> 15.960162 | D20: =IF('Building B17'!O184>0,'Building B17'!O184, " ") -> 0.24497299 | E20: =IF('Building B17'!Q184>0,'Building B17'!Q184, " ") -> 2.0286826 | F20: =IF('Building B17'!R184>0,'Building B17'!R184, " ") -> 155.49774 | H20: ='Building B17'!I200 -> 156964.76 | M20: =SUM(G20:L20) -> 156964.76
A21: 1.5.4 | B21: Final Survey | H21: ='Building B17'!I202 -> 170610.12 | M21: =SUM(G21:L21) -> 170610.12
A22: 1.6 | B22: Site Remediation | F22: =IF('Building B17'!R204>0,'Building B17'!R204, " ") -> 542.69535
A23: 1.6.1 | B23: Remove Building | H23: ='Building B17'!I205 -> 320487.65 | M23: =SUM(G23:L23) -> 320487.65
A24: 1.6.2 | B24: Grade and Seed | H24: ='Building B17'!I206 -> 22280.855 | M24: =SUM(G24:L24) -> 22280.855
A25: 1.6.3 | B25: Backfill | H25: ='Building B17'!I207 -> 51041.169 | M25: =SUM(G25:L25) -> 51041.169
A26: 1.7 | B26: Waste Disposal | J26: =IF('Building B17'!V210>0,'Building B17'!V210, " ") -> 2007.338 | L26: =IF('Building B17'!Y210>0,'Building B17'!Y210, " ") -> 369847.45 | M26: =SUM(G26:L26) -> 371854.79
B27: TOTAL | C27: =IF('Building B17'!N5>0,'Building B17'!N5, " ") -> 15.960162 | D27: =IF('Building B17'!O5>0,'Building B17'!O5, " ") -> 0.24497299 | E27: =IF('Building B17'!Q5>0,'Building B17'!Q5, " ") -> 2.0286826 | F27: =IF('Building B17'!R5>0,'Building B17'!R5, " ") -> 698.19309 | G27: =SUM(G6:G26) -> 649056.62 | H27: =SUM(H6:H26) -> 1644808.1 | I27: =SUM(I6:I26) -> 0 | J27: =SUM(J6:J26) -> 2007.338 | K27: =SUM(K6:K26) -> 0 | L27: =SUM(L6:L26) -> 369847.45 | M27: =SUM(M6:M26) -> 2665719.5
B28: NOTE: Cost included in overall staff costs
A30: WBS | B30: Description | C30: LSA Waste (M3) | D30: Hazardous Waste Vol (M3) | E30: Mixed Waste Vol (M3) | F30: Clean Waste Vol. (M3) | G30: Mat's, Consumables & Equip. | H30: Labor Cost | I30: LSA Waste Cost (TBD) | J30: Hazardous Waste Cost | K30: Mixed Waste Cost | L30: Clean Waste Cost | M30: Total Cost
A31: 1.0 | B31: Building B18
A32: 1.1 | B32: Project Management
A33: 1.1.1 | B33: Staff | H33: ='Building B18'!T8 -> 134378.1 | M33: =SUM(G33:L33) -> 134378.1
A34: 1.1.2 | B34: Equipment, Material & Consumables | G34: ='Building B18'!S8 -> 461768.17 | M34: =SUM(G34:L34) -> 461768.17
A35: 1.2 | B35: Project Planning
A36: 1.2.1 | B36: Procedure Development | H36: ='Building B18'!T68 -> 22935.2 | M36: =SUM(G36:L36) -> 22935.2
A37: 1.2.2 | B37: QA and Safety Documents | H37: ='Building B18'!T75 -> 22935.2 | M37: =SUM(G37:L37) -> 22935.2
A38: 1.2.3 | B38: Mobilization | H38: ='Building B18'!T82 -> 123378.7 | M38: =SUM(G38:L38) -> 123378.7
A39: 1.3 | B39: Preliminary Site Investigation | M39: =SUM(G39:L39) -> 0
A40: 1.3.1 | B40: Decontamination Readiness Review | H40: See Note 1 | M40: =SUM(G40:L40) -> 0
A41: 1.3.2 | B41: Site Prep | H41: ='Building B18'!T118 -> 44658.24 | M41: =SUM(G41:L41) -> 44658.24
A42: 1.4 | B42: Detailed Characterization | H42: ='Building B18'!T177 -> 297721.6 | M42: =SUM(G42:L42) -> 297721.6
A43: 1.5 | B43: Decontamination
...

Sheet Building B17
A1: B 17 DATA - Data highlighted in GREEN can be adjusted as needed
J2: Uncorrected Duration
I3: Crew | J3: (No. of Hours) | K3: Prod. Factor | L3: Adjusted Duration (hrs) | M3: Man-hours | N3: LSA Waste Disp. Vol (cm) | O3: Hazardous Waste Vol (cm) | Q3: Mixed Waste Volume (cm) | R3: Clean Waste Volume (cm) | S3: Materials, Consumables & Equipment | T3: Labor Cost | U3: LSA Waste Costs | V3: Hazardous Waste Costs | W3: LSA Waste Costs | X3: Mixed Waste Costs | Y3: Clean Waste Costs | Z3: Total Cost
A5: 1.0 | B5: Building B17 | L5: =L7+L65+L117+L176+L184+L204 -> 631 | M5: =M7+M65+M117+M176+M184+M204 -> 3073 | N5: =N7+N65+N117+N176+N184+N204 -> 15.960162 | O5: =O7+O65+O117+O176+O184+O204 -> 0.24497299 | Q5: =Q7+Q65+Q117+Q176+Q184+Q204 -> 2.0286826 | R5: =R7+R65+R117+R176+R184+R204 -> 698.19309 | S5: =S7+S65+S117+S176+S184+S204+S210 -> 649056.62 | T5: =T7+T65+T117+T176+T184+T204+T210 -> 1644808.1 | V5: =V7+V65+V117+V176+V184+V204+V210 -> 2007.338 | Y5: =Y7+Y65+Y117+Y176+Y184+Y204+Y210 -> 369847.45 | Z5: =SUM(S5:Y5) -> 2665719.5
A7: 1.1 | B7: Project Management | S7: =IF(G17="US",(H45+M57+K59+K61+K63)*Inputs!C37,(H45+M57+K59+K61+K63)) -> 649056.62 | T7: =I14 -> 268756.2 | Z7: =SUM(S7:Y7) -> 917812.82
A9: 1.1.1 | B9: Staff | E9: Number | F9: Rate | G9: Duration, days* | H9: Use Factor | I9: Cost | J9: Man-hours
B10: =Inputs!A$51 -> Portfolio Manager | E10: 1 | F10: =Inputs!E51 -> 157.87 | G10: =Inputs!B$144 -> 180 | H10: 0.25 | I10: =H10*G10*F10*E10*8 -> 56833.2 | J10: =H10*G10*10 -> 450
B11: =Inputs!A$50 -> Senior Project Manager / Characterization SME | E11: 1 | F11: =Inputs!E50 -> 127.28 | G11: =Inputs!B$144 -> 180 | H11: 0.5 | I11: =H11*G11*F11*E11*10 -> 114552 | J11: =H11*G11*10 -> 900
B12: =Inputs!A$49 -> Project Manager / Waste Management | E12: 1 | F12: =Inputs!E49 -> 108.19 | G12: =Inputs!B$144 -> 180 | H12: 0.5 | I12: =H12*G12*F12*E12*10 -> 97371 | J12: =H12*G12*10 -> 900
B13: =Inputs!A$48 -> Decom Technician / Safety SME | E13: 0 | F13: =Inputs!E48 -> 89.25 | G13: =Inputs!B$144 -> 180 | H13: 1 | I13: =H13*G13*F13*E13*10 -> 0 | J13: =H13*G13*10 -> 1800
E14: =SUM(E10:E13) -> 3 | I14: =SUM(I10:I13) -> 268756.2 | J14: =SUM(J10:J13) -> 4050
A16: 1.1.2 | B16: Equipment & Materials
G17: =Inputs!D85 -> US
C18: Equipment | F18: Quantity | G18: Rate | H18: Escalated Cost
C19: HEPA filter systems | F19: =IF(Inputs!$F$139=Inputs!$C$86,Inputs!C88,IF(Inputs!$F$139=Inputs!$G$86,Inputs!G88,IF(Inputs!$F$139=Inputs!$J$86,Inputs!J88,IF(Inputs!$F$139=Inputs!$M$86,Inputs!M88,"na")))) -> 2 | G19: =Inputs!D88 -> 3598.14 | H19: =G19*F19*(1+Inputs!$F$86) -> 11371.124
C20: Replacement filters | F20: =IF(Inputs!$F$139=Inputs!$C$86,Inputs!C89,IF(Inputs!$F$139=Inputs!$G$86,Inputs!G89,IF(Inputs!$F$139=Inputs!$J$86,Inputs!J89,IF(Inputs!$F$139=Inputs!$M$86,Inputs!M89,"na")))) -> 24 | G20: =Inputs!D89 -> 581.07 | H20: =G20*F20*(1+Inputs!$F$86) -> 22036.115
C21: Respirator | F21: =IF(Inputs!$F$139=Inputs!$C$86,Inputs!C90,IF(Inputs!$F$139=Inputs!$G$86,Inputs!G90,IF(Inputs!$F$139=Inputs!$J$86,Inputs!J90,IF(Inputs!$F$139=Inputs!$M$86,Inputs!M90,"na")))) -> 12 | G21: =Inputs!D90 -> 259 | H21: =G21*F21*(1+Inputs!$F$86) -> 4911.0725
C22: Rad/Vac wet-dry high eff. vacuum | F22: =IF(Inputs!$F$139=Inputs!$C$86,Inputs!C91,IF(Inputs!$F$139=Inputs!$G$86,Inputs!G91,IF(Inputs!$F$139=Inputs!$J$86,Inputs!J91,IF(Inputs!$F$139=Inputs!$M$86,Inputs!M91,"na")))) -> 2 | G22: =Inputs!D91 -> 3879 | H22: =G22*F22*(1+Inputs!$F$86) -> 12258.72
C23: Rad/Vac wet-dry high eff. vacuum filters | F23: =IF(Inputs!$F$139=Inputs!$C$86,Inputs!C92,IF(Inputs!$F$139=Inputs!$G$86,Inputs!G92,IF(Inputs!$F$139=Inputs!$J$86,Inputs!J92,IF(Inputs!$F$139=Inputs!$M$86,Inputs!M92,"na")))) -> 5 | G23: =Inputs!D92 -> 412 | H23: =G23*F23*(1+Inputs!$F$86) -> 3255.0867
C24: Reciprocating Saws | F24: =IF(Inputs!$F$139=Inputs!$C$86,Inputs!C93,IF(Inputs!$F$139=Inputs!$G$86,Inputs!G93,IF(Inputs!$F$139=Inputs!$J$86,Inputs!J93,IF(Inputs!$F$139=Inputs!$M$86,Inputs!M93,"na")))) -> 5 | G24: =Inputs!D93 -> 1252.26 | H24: =G24*F24*(1+Inputs!$F$86) -> 9893.7254
C25: Pneumatic chipping hammers | F25: =IF(Inputs!$F$139=Inputs!$C$86,Inputs!C94,IF(Inputs!$F$139=Inputs!$G$86,Inputs!G94,IF(Inputs!$F$139=Inputs!$J$86,Inputs!J94,IF(Inputs!$F$139=Inputs!$M$86,Inputs!M94,"na")))) -> 2 | G25: =Inputs!D94 -> 1606.71 | H25: =G25*F25*(1+Inputs!$F$86) -> 5077.6508
C26: Chipping hammer blades | F26: =IF(Inputs!$F$139=Inputs!$C$86,Inputs!C95,IF(Inputs!$F$139=Inputs!$G$86,Inputs!G95,IF(Inputs!$F$139=Inputs!$J$86,Inputs!J95,IF(Inputs!$F$139=Inputs!$M$86,Inputs!M95,"na")))) -> 20 | G26: =Inputs!D95 -> 27.42 | H26: =G26*F26*(1+Inputs!$F$86) -> 866.54832
C27: Purchase an air compressor: | F27: =IF(Inputs!$F$139=Inputs!$C$86,Inputs!C96,IF(Inputs!$F$139=Inputs!$G$86,Inputs!G96,IF(Inputs!$F$139=Inputs!$J$86,Inputs!J96,IF(Inputs!$F$139=Inputs!$M$86,Inputs!M96,"na")))) -> 2 | G27: =Inputs!D96 -> 1723.44 | H27: =G27*F27*(1+Inputs!$F$86) -> 5446.5501
C28: Jackhammer | F28: =IF(Inputs!$F$139=Inputs!$C$86,Inputs!C97,IF(Inputs!$F$139=Inputs!$G$86,Inputs!G97,IF(Inputs!$F$139=Inputs!$J$86,Inputs!J97,IF(Inputs!$F$139=Inputs!$M$86,Inputs!M97,"na")))) -> 4 | G28: =Inputs!D97 -> 1417.11 | H28: =G28*F28*(1+Inputs!$F$86) -> 8956.9241
C29: Jackhammer Chisels | F29: =IF(Inputs!$F$139=Inputs!$C$86,Inputs!C98,IF(Inputs!$F$139=Inputs!$G$86,Inputs!G98,IF(Inputs!$F$139=Inputs!$J$86,Inputs!J98,IF(Inputs!$F$139=Inputs!$M$86,Inputs!M98,"na")))) -> 10 | G29: =Inputs!D98 -> 24.35 | H29: =G29*F29*(1+Inputs!$F$86) -> 384.76389
C30: Safety glasses | F30: =IF(Inputs!$F$139=Inputs!$C$86,Inputs!C99,IF(Inputs!$F$139=Inputs!$G$86,Inputs!G99,IF(Inputs!$F$139=Inputs!$J$86,Inputs!J99,IF(Inputs!$F$139=Inputs!$M$86,Inputs!M99,"na")))) -> 15 | G30: =Inputs!D99 -> 8.6 | H30: =G30*F30*(1+Inputs!$F$86) -> 203.83795
... C44: Crane rental for building removal | F44: =IF(Inputs!$F$139=Inputs!$C$86,Inputs!C113,IF(Inputs!$F$139=Inputs!$G$86,Inputs!G113,IF(Inputs!$F$139=Inputs!$J$86,Inputs!J113,IF(Inputs!$F$139=Inputs!$M$86,Inputs!M113,"na")))) -> 1 | G44: =Inputs!D113 -> 15600 | H44: =G44*F44*(1+Inputs!$F$86) -> 24650.171
H45: =SUM(H19:H44) -> 232543.75
L46: =Inputs!H115 -> US
C47: Consumables | E47: Quantity | G47: Duration | I47: # workers | J47: quantity | K47: Unit Qty | L47: Unit Cost | M47: Escalated Cost
C48: Coveralls | E48: =IF(Inputs!$F$139=Inputs!$C$86,Inputs!B117,IF(Inputs!$F$139=Inputs!$G$86,Inputs!D117,IF(Inputs!$F$139=Inputs!$J$86,Inputs!E117,IF(Inputs!$F$139=Inputs!$M$86,Inputs!F117,"na")))) -> 2 | F48: /man/day | G48: =Inputs!B145 -> 90 | H48: days | I48: =Inputs!F$148 -> 12 | J48: =I48*G48*E48 -> 2160 | K48: 1 | L48: =Inputs!H117 -> 11 | M48: =J48/K48*L48*(1+Inputs!$F$86) -> 37544.107
C49: Hoods | E49: =IF(Inputs!$F$139=Inputs!$C$86,Inputs!B118,IF(Inputs!$F$139=Inputs!$G$86,Inputs!D118,IF(Inputs!$F$139=Inputs!$J$86,Inputs!E118,IF(Inputs!$F$139=Inputs!$M$86,Inputs!F118,"na")))) -> 0.1 | F49: /man/day | G49: =Inputs!B145 -> 90 | H49: days | I49: =Inputs!F$148 -> 12 | J49: =I49*G49*E49 -> 108 | K49: 1 | L49: =Inputs!H118 -> 0 | M49: =J49/K49*L49*(1+Inputs!$F$86) -> 0
C50: Shoe covers | E50: =IF(Inputs!$F$139=Inputs!$C$86,Inputs!B119,IF(Inputs!$F$139=Inputs!$G$86,Inputs!D119,IF(Inputs!$F$139=Inputs!$J$86,Inputs!E119,IF(Inputs!$F$139=Inputs!$M$86,Inputs!F119,"na")))) -> 4 | F50: /man/day | G50: =Inputs!B145 -> 90 | H50: days | I50: =Inputs!F$148 -> 12 | J50: =I50*G50*E50 -> 4320 | K50: 1 | L50: =Inputs!H119 -> 0.94 | M50: =J50/K50*L50*(1+Inputs!$F$86) -> 6416.6291
C51: Latex gloves | E51: =IF(Inputs!$F$139=Inputs!$C$86,Inputs!B120,IF(Inputs!$F$139=Inputs!$G$86,Inputs!D120,IF(Inputs!$F$139=Inputs!$J$86,Inputs!E120,IF(Inputs!$F$139=Inputs!$M$86,Inputs!F120,"na")))) -> 4 | F51: /man/day | G51: =Inputs!B145 -> 90 | H51: days | I51: =Inputs!F$148 -> 12 | J51: =I51*G51*E51 -> 4320 | K51: 1 | L51: =Inputs!H120 -> 0.94 | M51: =J51/K51*L51*(1+Inputs!$F$86) -> 6416.6291
C52: Rubber overshoes | E52: =IF(Inputs!$F$139=Inputs!$C$86,Inputs!B121,IF(Inputs!$F$139=Inputs!$G$86,Inputs!D121,IF(Inputs!$F$139=Inputs!$J$86,Inputs!E121,IF(Inputs!$F$139=Inputs!$M$86,Inputs!F121,"na")))) -> 0.01 | F52: /man/day | G52: =Inputs!B145 -> 90 | H52: days | I52: =Inputs!F$148 -> 12 | J52: =I52*G52*E52 -> 10.8 | K52: 1 | L52: =Inputs!H121 -> 3 | M52: =J52/K52*L52*(1+Inputs!$F$86) -> 51.196509
C53: Gloves | E53: =IF(Inputs!$F$139=Inputs!$C$86,Inputs!B122,IF(Inputs!$F$139=Inputs!$G$86,Inputs!D122,IF(Inputs!$F$139=Inputs!$J$86,Inputs!E122,IF(Inputs!$F$139=Inputs!$M$86,Inputs!F122,"na")))) -> 0.01 | F53: /man/day | G53: =Inputs!B145 -> 90 | H53: days | I53: =Inputs!F$148 -> 12 | J53: =I53*G53*E53 -> 10.8 | K53: 1 | L53: =Inputs!H122 -> 2 | M53: =J53/K53*L53*(1+Inputs!$F$86) -> 34.131006
C54: Dosimeters | E54: =IF(Inputs!$F$139=Inputs!$C$86,Inputs!B123,IF(Inputs!$F$139=Inputs!$G$86,Inputs!D123,IF(Inputs!$F$139=Inputs!$J$86,Inputs!E123,IF(Inputs!$F$139=Inputs!$M$86,Inputs!F123,"na")))) -> 1 | F54: /man/year | G54: =1/3 -> 0.33333333 | H54: year | I54: =Inputs!F$148 -> 12 | J54: =I54*G54*E54 -> 4 | K54: 1 | L54: =Inputs!H123 -> 200 | M54: =J54/K54*L54*(1+Inputs!$F$86) -> 1264.1113
C55: TLDs | E55: =IF(Inputs!$F$139=Inputs!$C$86,Inputs!B124,IF(Inputs!$F$139=Inputs!$G$86,Inputs!D124,IF(Inputs!$F$139=Inputs!$J$86,Inputs!E124,IF(Inputs!$F$139=Inputs!$M$86,Inputs!F124,"na")))) -> 1 | F55: /man/mo | G55: 3 | H55: month | I55: =Inputs!F$148 -> 12 | J55: =I55*G55*E55 -> 36 | K55: 1 | L55: =Inputs!H124 -> 3 | M55: =J55/K55*L55*(1+Inputs!$F$86) -> 170.65503
C56: Bioassays | E56: =IF(Inputs!$F$139=Inputs!$C$86,Inputs!B125,IF(Inputs!$F$139=Inputs!$G$86,Inputs!D125,IF(Inputs!$F$139=Inputs!$J$86,Inputs!E125,IF(Inputs!$F$139=Inputs!$M$86,Inputs!F125,"na")))) -> 2 | F56: /man/year | G56: 1 | H56: year | I56: =Inputs!F$148 -> 12 | J56: =I56*G56*E56 -> 24 | K56: 1 | L56: =Inputs!H125 -> 250 | M56: =J56/K56*L56*(1+Inputs!$F$86) -> 9480.835
C57: (Bioassays for aver. crew & management) | M57: =SUM(M48:M56) -> 61378.294
...

Sheet Building B54
A1: B 54 DATA - Data highlighted in GREEN can be adjusted as needed
J2: Uncorrected Duration
I3: Crew | J3: (No. of Hours) | K3: Prod. Factor | L3: Adjusted Duration (hrs) | M3: Man-hours | N3: LSA Waste Disp. Vol (cm) | O3: Hazardous Waste Vol (cm) | Q3: Mixed Waste Volume (cm) | R3: Clean Waste Volume (cm) | S3: Materials, Consumables & Equipment | T3: Labor Cost | U3: LSA Waste Costs | V3: Hazardous Waste Costs | W3: LSA Waste Costs | X3: Mixed Waste Costs | Y3: Clean Waste Costs | Z3: Total Cost
A6: 1.0 | B6: Building B54 | L6: =L8+L66+L118+L177+L185+L207 -> 631 | M6: =M8+M66+M118+M177+M185+M207 -> 8205 | N6: =N8+N66+N118+N177+N185+N207 -> 30.356693 | O6: =O8+O66+O118+O177+O185+O207 -> 328.66293 | Q6: =Q8+Q66+Q118+Q177+Q185+Q207 -> 3.4695083 | R6: =R8+R66+R118+R177+R185+R207 -> 1341.2095 | S6: =S8+S66+S118+S177+S185+S207+S214 -> 1975720.3 | T6: =T8+T66+T118+T177+T185+T207+T214 -> 11155053 | V6: =V8+V66+V118+V177+V185+V207+V214 -> 290166.02 | X6: =X8+X66+X118+X177+X185+X207+X214 -> 27902.761 | Y6: =Y8+Y66+Y118+Y177+Y185+Y207+Y214 -> 710466.68 | Z6: =SUM(S6:Y6) -> 14159309
A8: 1.1 | B8: Project Management | S8: =IF(G18="US",(H46+M58+K60+K62+K64)*Inputs!C37,(H46+M58+K60+K62+K64)) -> 1975720.3 | T8: =I15 -> 614958.12 | Z8: =SUM(S8:Y8) -> 2590678.4
A10: 1.1.1 | B10: Staff | E10: Number | F10: Rate | G10: Duration, days* | H10: Use Factor | I10: Cost | J10: Man-hours
B11: =Inputs!A$51 -> Portfolio Manager | E11: 1 | F11: =Inputs!E51 -> 157.87 | G11: =Inputs!G$172 -> 252 | H11: 1 | I11: =H11*G11*F11*E11*8 -> 318265.92 | J11: =H11*G11*10 -> 2520
B12: =Inputs!A$50 -> Senior Project Manager / Characterization SME | E12: 1 | F12: =Inputs!E50 -> 127.28 | G12: =Inputs!G$172 -> 252 | H12: 0.5 | I12: =H12*G12*F12*E12*10 -> 160372.8 | J12: =H12*G12*10 -> 1260
B13: =Inputs!A$49 -> Project Manager / Waste Management | E13: 1 | F13: =Inputs!E49 -> 108.19 | G13: =Inputs!G$172 -> 252 | H13: 0.5 | I13: =H13*G13*F13*E13*10 -> 136319.4 | J13: =H13*G13*10 -> 1260
B14: =Inputs!A$48 -> Decom Technician / Safety SME | E14: 0 | F14: =Inputs!E48 -> 89.25 | G14: =Inputs!G$172 -> 252 | H14: 1 | I14: =H14*G14*F14*E14*10 -> 0 | J14: =H14*G14*10 -> 2520
E15: =SUM(E11:E14) -> 3 | I15: =SUM(I11:I14) -> 614958.12 | J15: =SUM(J11:J14) -> 7560
A17: 1.1.2 | B17: Equipment & Materials
G18: =Inputs!D85 -> US
C19: Equipment | F19: Quantity | G19: Rate | H19: Escalated Cost
C20: HEPA filter systems | F20: =IF(Inputs!$B$169=Inputs!$C$86,Inputs!C88,IF(Inputs!$B$169=Inputs!$G$86,Inputs!G88,IF(Inputs!$B$169=Inputs!$J$86,Inputs!J88,IF(Inputs!$B$169=Inputs!$M$86,Inputs!M88,"na")))) -> 2 | G20: =Inputs!D88 -> 3598.14 | H20: =G20*F20*(1+Inputs!$F$86) -> 11371.124
C21: Replacement filters | F21: =IF(Inputs!$B$169=Inputs!$C$86,Inputs!C89,IF(Inputs!$B$169=Inputs!$G$86,Inputs!G89,IF(Inputs!$B$169=Inputs!$J$86,Inputs!J89,IF(Inputs!$B$169=Inputs!$M$86,Inputs!M89,"na")))) -> 24 | G21: =Inputs!D89 -> 581.07 | H21: =G21*F21*(1+Inputs!$F$86) -> 22036.115
C22: Respirator | F22: =IF(Inputs!$B$169=Inputs!$C$86,Inputs!C90,IF(Inputs!$B$169=Inputs!$G$86,Inputs!G90,IF(Inputs!$B$169=Inputs!$J$86,Inputs!J90,IF(Inputs!$B$169=Inputs!$M$86,Inputs!M90,"na")))) -> 12 | G22: =Inputs!D90 -> 259 | H22: =G22*F22*(1+Inputs!$F$86) -> 4911.0725
C23: Rad/Vac wet-dry high eff. vacuum | F23: =IF(Inputs!$B$169=Inputs!$C$86,Inputs!C91,IF(Inputs!$B$169=Inputs!$G$86,Inputs!G91,IF(Inputs!$B$169=Inputs!$J$86,Inputs!J91,IF(Inputs!$B$169=Inputs!$M$86,Inputs!M91,"na")))) -> 1 | G23: =Inputs!D91 -> 3879 | H23: =G23*F23*(1+Inputs!$F$86) -> 6129.3598
C24: Rad/Vac wet-dry high eff. vacuum filters | F24: =IF(Inputs!$B$169=Inputs!$C$86,Inputs!C92,IF(Inputs!$B$169=Inputs!$G$86,Inputs!G92,IF(Inputs!$B$169=Inputs!$J$86,Inputs!J92,IF(Inputs!$B$169=Inputs!$M$86,Inputs!M92,"na")))) -> 5 | G24: =Inputs!D92 -> 412 | H24: =G24*F24*(1+Inputs!$F$86) -> 3255.0867
C25: Reciprocating Saws | F25: =IF(Inputs!$B$169=Inputs!$C$86,Inputs!C93,IF(Inputs!$B$169=Inputs!$G$86,Inputs!G93,IF(Inputs!$B$169=Inputs!$J$86,Inputs!J93,IF(Inputs!$B$169=Inputs!$M$86,Inputs!M93,"na")))) -> 5 | G25: =Inputs!D93 -> 1252.26 | H25: =G25*F25*(1+Inputs!$F$86) -> 9893.7254
C26: Pneumatic chipping hammers | F26: =IF(Inputs!$B$169=Inputs!$C$86,Inputs!C94,IF(Inputs!$B$169=Inputs!$G$86,Inputs!G94,IF(Inputs!$B$169=Inputs!$J$86,Inputs!J94,IF(Inputs!$B$169=Inputs!$M$86,Inputs!M94,"na")))) -> 2 | G26: =Inputs!D94 -> 1606.71 | H26: =G26*F26*(1+Inputs!$F$86) -> 5077.6508
C27: Chipping hammer blades | F27: =IF(Inputs!$B$169=Inputs!$C$86,Inputs!C95,IF(Inputs!$B$169=Inputs!$G$86,Inputs!G95,IF(Inputs!$B$169=Inputs!$J$86,Inputs!J95,IF(Inputs!$B$169=Inputs!$M$86,Inputs!M95,"na")))) -> 20 | G27: =Inputs!D95 -> 27.42 | H27: =G27*F27*(1+Inputs!$F$86) -> 866.54832
C28: Purchase an air compressor: | F28: =IF(Inputs!$B$169=Inputs!$C$86,Inputs!C96,IF(Inputs!$B$169=Inputs!$G$86,Inputs!G96,IF(Inputs!$B$169=Inputs!$J$86,Inputs!J96,IF(Inputs!$B$169=Inputs!$M$86,Inputs!M96,"na")))) -> 2 | G28: =Inputs!D96 -> 1723.44 | H28: =G28*F28*(1+Inputs!$F$86) -> 5446.5501
C29: Jackhammer | F29: =IF(Inputs!$B$169=Inputs!$C$86,Inputs!C97,IF(Inputs!$B$169=Inputs!$G$86,Inputs!G97,IF(Inputs!$B$169=Inputs!$J$86,Inputs!J97,IF(Inputs!$B$169=Inputs!$M$86,Inputs!M97,"na")))) -> 4 | G29: =Inputs!D97 -> 1417.11 | H29: =G29*F29*(1+Inputs!$F$86) -> 8956.9241
C30: Jackhammer Chisels | F30: =IF(Inputs!$B$169=Inputs!$C$86,Inputs!C98,IF(Inputs!$B$169=Inputs!$G$86,Inputs!G98,IF(Inputs!$B$169=Inputs!$J$86,Inputs!J98,IF(Inputs!$B$169=Inputs!$M$86,Inputs!M98,"na")))) -> 10 | G30: =Inputs!D98 -> 24.35 | H30: =G30*F30*(1+Inputs!$F$86) -> 384.76389
C31: Safety glasses | F31: =IF(Inputs!$B$169=Inputs!$C$86,Inputs!C99,IF(Inputs!$B$169=Inputs!$G$86,Inputs!G99,IF(Inputs!$B$169=Inputs!$J$86,Inputs!J99,IF(Inputs!$B$169=Inputs!$M$86,Inputs!M99,"na")))) -> 15 | G31: =Inputs!D99 -> 8.6 | H31: =G31*F31*(1+Inputs!$F$86) -> 203.83795
... C45: Crane rental for building removal | F45: =IF(Inputs!$B$169=Inputs!$C$86,Inputs!C113,IF(Inputs!$B$169=Inputs!$G$86,Inputs!G113,IF(Inputs!$B$169=Inputs!$J$86,Inputs!J113,IF(Inputs!$B$169=Inputs!$M$86,Inputs!M113,"na")))) -> 1 | G45: =Inputs!D113 -> 15600 | H45: =G45*F45*(1+Inputs!$F$86) -> 24650.171
H46: =SUM(H20:H45) -> 226414.4
C48: Consumables | E48: Quantity | G48: Duration | I48: # workers | J48: quantity | K48: Unit Qty | L48: Unit Cost | M48: Escalated Cost
C49: Coveralls | E49: =IF(Inputs!$B$169=Inputs!$C$86,Inputs!C117,IF(Inputs!$B$169=Inputs!$G$86,Inputs!D117,IF(Inputs!$B$169=Inputs!$J$86,Inputs!E117,IF(Inputs!$B$169=Inputs!$M$86,Inputs!F117,"na")))) -> 2 | F49: /man/day | G49: =Inputs!B$172 -> 180 | H49: days | I49: =Inputs!H$175 -> 24 | J49: =I49*G49*E49 -> 8640 | K49: 1 | L49: =Inputs!H117 -> 11 | M49: =J49/K49*L49*(1+Inputs!$F$86) -> 150176.43
C50: Hoods | E50: =IF(Inputs!$B$169=Inputs!$C$86,Inputs!C118,IF(Inputs!$B$169=Inputs!$G$86,Inputs!D118,IF(Inputs!$B$169=Inputs!$J$86,Inputs!E118,IF(Inputs!$B$169=Inputs!$M$86,Inputs!F118,"na")))) -> 0.1 | F50: /man/day | G50: =Inputs!B$172 -> 180 | H50: days | I50: =Inputs!H$175 -> 24 | J50: =I50*G50*E50 -> 432 | K50: 1 | L50: =Inputs!H118 -> 0 | M50: =J50/K50*L50*(1+Inputs!$F$86) -> 0
C51: Shoe covers | E51: =IF(Inputs!$B$169=Inputs!$C$86,Inputs!C119,IF(Inputs!$B$169=Inputs!$G$86,Inputs!D119,IF(Inputs!$B$169=Inputs!$J$86,Inputs!E119,IF(Inputs!$B$169=Inputs!$M$86,Inputs!F119,"na")))) -> 4 | F51: /man/day | G51: =Inputs!B$172 -> 180 | H51: days | I51: =Inputs!H$175 -> 24 | J51: =I51*G51*E51 -> 17280 | K51: 1 | L51: =Inputs!H119 -> 0.94 | M51: =J51/K51*L51*(1+Inputs!$F$86) -> 25666.517
C52: Latex gloves | E52: =IF(Inputs!$B$169=Inputs!$C$86,Inputs!C120,IF(Inputs!$B$169=Inputs!$G$86,Inputs!D120,IF(Inputs!$B$169=Inputs!$J$86,Inputs!E120,IF(Inputs!$B$169=Inputs!$M$86,Inputs!F120,"na")))) -> 4 | F52: /man/day | G52: =Inputs!B$172 -> 180 | H52: days | I52: =Inputs!H$175 -> 24 | J52: =I52*G52*E52 -> 17280 | K52: 1 | L52: =Inputs!H120 -> 0.94 | M52: =J52/K52*L52*(1+Inputs!$F$86) -> 25666.517
C53: Rubber overshoes | E53: =IF(Inputs!$B$169=Inputs!$C$86,Inputs!C121,IF(Inputs!$B$169=Inputs!$G$86,Inputs!D121,IF(Inputs!$B$169=Inputs!$J$86,Inputs!E121,IF(Inputs!$B$169=Inputs!$M$86,Inputs!F121,"na")))) -> 0.01 | F53: /man/day | G53: =Inputs!B$172 -> 180 | H53: days | I53: =Inputs!H$175 -> 24 | J53: =I53*G53*E53 -> 43.2 | K53: 1 | L53: =Inputs!H121 -> 3 | M53: =J53/K53*L53*(1+Inputs!$F$86) -> 204.78604
C54: Gloves | E54: =IF(Inputs!$B$169=Inputs!$C$86,Inputs!C122,IF(Inputs!$B$169=Inputs!$G$86,Inputs!D122,IF(Inputs!$B$169=Inputs!$J$86,Inputs!E122,IF(Inputs!$B$169=Inputs!$M$86,Inputs!F122,"na")))) -> 0.01 | F54: /man/day | G54: =Inputs!B$172 -> 180 | H54: days | I54: =Inputs!H$175 -> 24 | J54: =I54*G54*E54 -> 43.2 | K54: 1 | L54: =Inputs!H122 -> 2 | M54: =J54/K54*L54*(1+Inputs!$F$86) -> 136.52402
C55: Dosimeters | E55: =IF(Inputs!$B$169=Inputs!$C$86,Inputs!C123,IF(Inputs!$B$169=Inputs!$G$86,Inputs!D123,IF(Inputs!$B$169=Inputs!$J$86,Inputs!E123,IF(Inputs!$B$169=Inputs!$M$86,Inputs!F123,"na")))) -> 1 | F55: /man/year | G55: =1/3 -> 0.33333333 | H55: year | I55: =Inputs!H$175 -> 24 | J55: =I55*G55*E55 -> 8 | K55: 1 | L55: =Inputs!H123 -> 200 | M55: =J55/K55*L55*(1+Inputs!$F$86) -> 2528.2227
C56: TLDs | E56: =IF(Inputs!$B$169=Inputs!$C$86,Inputs!C124,IF(Inputs!$B$169=Inputs!$G$86,Inputs!D124,IF(Inputs!$B$169=Inputs!$J$86,Inputs!E124,IF(Inputs!$B$169=Inputs!$M$86,Inputs!F124,"na")))) -> 1 | F56: /man/mo | G56: 3 | H56: month | I56: =Inputs!H$175 -> 24 | J56: =I56*G56*E56 -> 72 | K56: 1 | L56: =Inputs!H124 -> 3 | M56: =J56/K56*L56*(1+Inputs!$F$86) -> 341.31006
C57: Bioassays | E57: =IF(Inputs!$B$169=Inputs!$C$86,Inputs!C125,IF(Inputs!$B$169=Inputs!$G$86,Inputs!D125,IF(Inputs!$B$169=Inputs!$J$86,Inputs!E125,IF(Inputs!$B$169=Inputs!$M$86,Inputs!F125,"na")))) -> 2 | F57: /man/year | G57: 1 | H57: year | I57: =Inputs!H$175 -> 24 | J57: =I57*G57*E57 -> 48 | K57: 1 | L57: =Inputs!H125 -> 250 | M57: =J57/K57*L57*(1+Inputs!$F$86) -> 18961.67
C58: (Bioassays for aver. crew & management) | M58: =SUM(M49:M57) -> 223681.97
C60: Small Tools - 2% of total labor costs = | G60: =(T6-T8) -> 10540095 | H60: labor costs x | I60: =Inputs!F128 -> 0.02 | J60: = | K60: =I60*G60 -> 210801.91
...

Sheet Building B18
A1: B 18 DATA - Data highlighted in GREEN can be adjusted as needed
J2: Uncorrected Duration
I3: Crew | J3: (No. of Hours) | K3: Prod. Factor | L3: Adjusted Duration (hrs) | M3: Man-hours | N3: LSA Waste Disp. Vol (cm) | O3: Hazardous Waste Vol (cm) | Q3: Mixed Waste Volume (cm) | R3: Clean Waste Volume (cm) | S3: Materials, Consumables & Equipment | T3: Labor Cost | U3: LSA Waste Costs | V3: Hazardous Waste Costs | W3: LSA Waste Costs | X3: Mixed Waste Costs | Y3: Clean Waste Costs | Z3: Total Cost
A6: 1.0 | B6: Building B18 | L6: =L8+L66+L118+L177+L185+L205 -> 663 | M6: =M8+M66+M118+M177+M185+M205 -> 5465 | N6: =N8+N66+N118+N177+N185+N205 -> 3450 | O6: =O8+O66+O118+O177+O185+O205 -> 0 | Q6: =Q8+Q66+Q118+Q177+Q185+Q205 -> 0 | R6: =R8+R66+R118+R177+R185+R205 -> 3450 | S6: =S8+S66+S118+S177+S185+S205+S211 -> 461768.17 | T6: =T8+T66+T118+T177+T185+T205+T211 -> 2851597.5 | V6: =V8+V66+V118+V177+V185+V205+V211 -> 0 | Y6: =Y8+Y66+Y118+Y177+Y185+Y205+Y211 -> 1827537 | Z6: =SUM(S6:Y6) -> 5140902.6
A8: 1.1 | B8: Project Management | S8: =IF(G18="US",(H46+M58+K60+K62+K64)*Inputs!C37,(H46+M58+K60+K62+K64)) -> 461768.17 | T8: =I15 -> 134378.1 | Z8: =SUM(S8:Y8) -> 596146.27
A10: 1.1.1 | B10: Staff | E10: Number | F10: Rate | G10: Duration, days* | H10: Use Factor | I10: Cost | J10: Man-hours
B11: =Inputs!A$51 -> Portfolio Manager | E11: 1 | F11: =Inputs!E51 -> 157.87 | G11: =Inputs!B$161 -> 90 | H11: 0.25 | I11: =H11*G11*F11*E11*8 -> 28416.6 | J11: =H11*G11*10 -> 225
B12: =Inputs!A$50 -> Senior Project Manager / Characterization SME | E12: 1 | F12: =Inputs!E50 -> 127.28 | G12: =Inputs!B$161 -> 90 | H12: 0.5 | I12: =H12*G12*F12*E12*10 -> 57276 | J12: =H12*G12*10 -> 450
B13: =Inputs!A$49 -> Project Manager / Waste Management | E13: 1 | F13: =Inputs!E49 -> 108.19 | G13: =Inputs!B$161 -> 90 | H13: 0.5 | I13: =H13*G13*F13*E13*10 -> 48685.5 | J13: =H13*G13*10 -> 450
B14: =Inputs!A$48 -> Decom Technician / Safety SME | E14: 0 | F14: =Inputs!E48 -> 89.25 | G14: =Inputs!B$161 -> 90 | H14: 1 | I14: =H14*G14*F14*E14*10 -> 0 | J14: =H14*G14*10 -> 900
E15: =SUM(E11:E14) -> 3 | I15: =SUM(I11:I14) -> 134378.1 | J15: =SUM(J11:J14) -> 2025
A17: 1.1.2 | B17: Equipment & Materials
G18: =Inputs!D85 -> US
C19: Equipment | F19: Quantity | G19: Rate | H19: Escalated Cost
C20: HEPA filter systems | F20: =IF(Inputs!$B$150=Inputs!$C$86,Inputs!C88,IF(Inputs!$B$150=Inputs!$G$86,Inputs!G88,IF(Inputs!$B$150=Inputs!$J$86,Inputs!J88,IF(Inputs!$B$150=Inputs!$M$86,Inputs!M88,"na")))) -> 0 | G20: =Inputs!D88 -> 3598.14 | H20: =G20*F20*(1+Inputs!$F$86) -> 0
C21: Replacement filters | F21: =IF(Inputs!$B$150=Inputs!$C$86,Inputs!C89,IF(Inputs!$B$150=Inputs!$G$86,Inputs!G89,IF(Inputs!$B$150=Inputs!$J$86,Inputs!J89,IF(Inputs!$B$150=Inputs!$M$86,Inputs!M89,"na")))) -> 0 | G21: =Inputs!D89 -> 581.07 | H21: =G21*F21*(1+Inputs!$F$86) -> 0
C22: Respirator | F22: =IF(Inputs!$B$150=Inputs!$C$86,Inputs!C90,IF(Inputs!$B$150=Inputs!$G$86,Inputs!G90,IF(Inputs!$B$150=Inputs!$J$86,Inputs!J90,IF(Inputs!$B$150=Inputs!$M$86,Inputs!M90,"na")))) -> 0 | G22: =Inputs!D90 -> 259 | H22: =G22*F22*(1+Inputs!$F$86) -> 0
C23: Rad/Vac wet-dry high eff. vacuum | F23: =IF(Inputs!$B$150=Inputs!$C$86,Inputs!C91,IF(Inputs!$B$150=Inputs!$G$86,Inputs!G91,IF(Inputs!$B$150=Inputs!$J$86,Inputs!J91,IF(Inputs!$B$150=Inputs!$M$86,Inputs!M91,"na")))) -> 0 | G23: =Inputs!D91 -> 3879 | H23: =G23*F23*(1+Inputs!$F$86) -> 0
C24: Rad/Vac wet-dry high eff. vacuum filters | F24: =IF(Inputs!$B$150=Inputs!$C$86,Inputs!C92,IF(Inputs!$B$150=Inputs!$G$86,Inputs!G92,IF(Inputs!$B$150=Inputs!$J$86,Inputs!J92,IF(Inputs!$B$150=Inputs!$M$86,Inputs!M92,"na")))) -> 0 | G24: =Inputs!D92 -> 412 | H24: =G24*F24*(1+Inputs!$F$86) -> 0
C25: Reciprocating Saws | F25: =IF(Inputs!$B$150=Inputs!$C$86,Inputs!C93,IF(Inputs!$B$150=Inputs!$G$86,Inputs!G93,IF(Inputs!$B$150=Inputs!$J$86,Inputs!J93,IF(Inputs!$B$150=Inputs!$M$86,Inputs!M93,"na")))) -> 0 | G25: =Inputs!D93 -> 1252.26 | H25: =G25*F25*(1+Inputs!$F$86) -> 0
C26: Pneumatic chipping hammers | F26: =IF(Inputs!$B$150=Inputs!$C$86,Inputs!C94,IF(Inputs!$B$150=Inputs!$G$86,Inputs!G94,IF(Inputs!$B$150=Inputs!$J$86,Inputs!J94,IF(Inputs!$B$150=Inputs!$M$86,Inputs!M94,"na")))) -> 2 | G26: =Inputs!D94 -> 1606.71 | H26: =G26*F26*(1+Inputs!$F$86) -> 5077.6508
C27: Chipping hammer blades | F27: =IF(Inputs!$B$150=Inputs!$C$86,Inputs!C95,IF(Inputs!$B$150=Inputs!$G$86,Inputs!G95,IF(Inputs!$B$150=Inputs!$J$86,Inputs!J95,IF(Inputs!$B$150=Inputs!$M$86,Inputs!M95,"na")))) -> 20 | G27: =Inputs!D95 -> 27.42 | H27: =G27*F27*(1+Inputs!$F$86) -> 866.54832
C28: Purchase an air compressor: | F28: =IF(Inputs!$B$150=Inputs!$C$86,Inputs!C96,IF(Inputs!$B$150=Inputs!$G$86,Inputs!G96,IF(Inputs!$B$150=Inputs!$J$86,Inputs!J96,IF(Inputs!$B$150=Inputs!$M$86,Inputs!M96,"na")))) -> 2 | G28: =Inputs!D96 -> 1723.44 | H28: =G28*F28*(1+Inputs!$F$86) -> 5446.5501
C29: Jackhammer | F29: =IF(Inputs!$B$150=Inputs!$C$86,Inputs!C97,IF(Inputs!$B$150=Inputs!$G$86,Inputs!G97,IF(Inputs!$B$150=Inputs!$J$86,Inputs!J97,IF(Inputs!$B$150=Inputs!$M$86,Inputs!M97,"na")))) -> 4 | G29: =Inputs!D97 -> 1417.11 | H29: =G29*F29*(1+Inputs!$F$86) -> 8956.9241
C30: Jackhammer Chisels | F30: =IF(Inputs!$B$150=Inputs!$C$86,Inputs!C98,IF(Inputs!$B$150=Inputs!$G$86,Inputs!G98,IF(Inputs!$B$150=Inputs!$J$86,Inputs!J98,IF(Inputs!$B$150=Inputs!$M$86,Inputs!M98,"na")))) -> 10 | G30: =Inputs!D98 -> 24.35 | H30: =G30*F30*(1+Inputs!$F$86) -> 384.76389
C31: Safety glasses | F31: =IF(Inputs!$B$150=Inputs!$C$86,Inputs!C99,IF(Inputs!$B$150=Inputs!$G$86,Inputs!G99,IF(Inputs!$B$150=Inputs!$J$86,Inputs!J99,IF(Inputs!$B$150=Inputs!$M$86,Inputs!M99,"na")))) -> 15 | G31: =Inputs!D99 -> 8.6 | H31: =G31*F31*(1+Inputs!$F$86) -> 203.83795
... C45: Crane rental for building removal | F45: =IF(Inputs!$B$150=Inputs!$C$86,Inputs!C113,IF(Inputs!$B$150=Inputs!$G$86,Inputs!G113,IF(Inputs!$B$150=Inputs!$J$86,Inputs!J113,IF(Inputs!$B$150=Inputs!$M$86,Inputs!M113,"na")))) -> 0 | G45: =Inputs!D113 -> 15600 | H45: =G45*F45*(1+Inputs!$F$86) -> 0
H46: =SUM(H20:H45) -> 87433.033
C48: Consumables | E48: Quantity | G48: Duration | I48: # workers | J48: quantity | K48: Unit Qty | L48: Unit Cost | M48: Escalated Cost
C49: Coveralls | E49: =IF(Inputs!$B$150=Inputs!$C$86,Inputs!C117,IF(Inputs!$B$150=Inputs!$G$86,Inputs!D117,IF(Inputs!$B$150=Inputs!$J$86,Inputs!E117,IF(Inputs!$B$150=Inputs!$M$86,Inputs!F117,"na")))) -> 0 | F49: /man/day | G49: =Inputs!B$161 -> 90 | H49: days | I49: =Inputs!F$166 -> 12 | J49: =I49*G49*E49 -> 0 | K49: 1 | L49: =Inputs!H117 -> 11 | M49: =J49/K49*L49*(1+Inputs!$F$86) -> 0
C50: Hoods | E50: =IF(Inputs!$B$150=Inputs!$C$86,Inputs!C118,IF(Inputs!$B$150=Inputs!$G$86,Inputs!D118,IF(Inputs!$B$150=Inputs!$J$86,Inputs!E118,IF(Inputs!$B$150=Inputs!$M$86,Inputs!F118,"na")))) -> 0 | F50: /man/day | G50: =Inputs!B$161 -> 90 | H50: days | I50: =Inputs!F$166 -> 12 | J50: =I50*G50*E50 -> 0 | K50: 1 | L50: =Inputs!H118 -> 0 | M50: =J50/K50*L50*(1+Inputs!$F$86) -> 0
C51: Shoe covers | E51: =IF(Inputs!$B$150=Inputs!$C$86,Inputs!C119,IF(Inputs!$B$150=Inputs!$G$86,Inputs!D119,IF(Inputs!$B$150=Inputs!$J$86,Inputs!E119,IF(Inputs!$B$150=Inputs!$M$86,Inputs!F119,"na")))) -> 0 | F51: /man/day | G51: =Inputs!B$161 -> 90 | H51: days | I51: =Inputs!F$166 -> 12 | J51: =I51*G51*E51 -> 0 | K51: 1 | L51: =Inputs!H119 -> 0.94 | M51: =J51/K51*L51*(1+Inputs!$F$86) -> 0
C52: Latex gloves | E52: =IF(Inputs!$B$150=Inputs!$C$86,Inputs!C120,IF(Inputs!$B$150=Inputs!$G$86,Inputs!D120,IF(Inputs!$B$150=Inputs!$J$86,Inputs!E120,IF(Inputs!$B$150=Inputs!$M$86,Inputs!F120,"na")))) -> 0 | F52: /man/day | G52: =Inputs!B$161 -> 90 | H52: days | I52: =Inputs!F$166 -> 12 | J52: =I52*G52*E52 -> 0 | K52: 1 | L52: =Inputs!H120 -> 0.94 | M52: =J52/K52*L52*(1+Inputs!$F$86) -> 0
C53: Rubber overshoes | E53: =IF(Inputs!$B$150=Inputs!$C$86,Inputs!C121,IF(Inputs!$B$150=Inputs!$G$86,Inputs!D121,IF(Inputs!$B$150=Inputs!$J$86,Inputs!E121,IF(Inputs!$B$150=Inputs!$M$86,Inputs!F121,"na")))) -> 0 | F53: /man/day | G53: =Inputs!B$161 -> 90 | H53: days | I53: =Inputs!F$166 -> 12 | J53: =I53*G53*E53 -> 0 | K53: 1 | L53: =Inputs!H121 -> 3 | M53: =J53/K53*L53*(1+Inputs!$F$86) -> 0
C54: Gloves | E54: =IF(Inputs!$B$150=Inputs!$C$86,Inputs!C122,IF(Inputs!$B$150=Inputs!$G$86,Inputs!D122,IF(Inputs!$B$150=Inputs!$J$86,Inputs!E122,IF(Inputs!$B$150=Inputs!$M$86,Inputs!F122,"na")))) -> 0 | F54: /man/day | G54: =Inputs!B$161 -> 90 | H54: days | I54: =Inputs!F$166 -> 12 | J54: =I54*G54*E54 -> 0 | K54: 1 | L54: =Inputs!H122 -> 2 | M54: =J54/K54*L54*(1+Inputs!$F$86) -> 0
C55: Dosimeters | E55: =IF(Inputs!$B$150=Inputs!$C$86,Inputs!C123,IF(Inputs!$B$150=Inputs!$G$86,Inputs!D123,IF(Inputs!$B$150=Inputs!$J$86,Inputs!E123,IF(Inputs!$B$150=Inputs!$M$86,Inputs!F123,"na")))) -> 0 | F55: /man/year | G55: 0.25 | H55: year | I55: =Inputs!F$166 -> 12 | J55: =I55*G55*E55 -> 0 | K55: 1 | L55: =Inputs!H123 -> 200 | M55: =J55/K55*L55*(1+Inputs!$F$86) -> 0
C56: TLDs | E56: =IF(Inputs!$B$150=Inputs!$C$86,Inputs!C124,IF(Inputs!$B$150=Inputs!$G$86,Inputs!D124,IF(Inputs!$B$150=Inputs!$J$86,Inputs!E124,IF(Inputs!$B$150=Inputs!$M$86,Inputs!F124,"na")))) -> 0 | F56: /man/mo | G56: 3 | H56: month | I56: =Inputs!F$166 -> 12 | J56: =I56*G56*E56 -> 0 | K56: 1 | L56: =Inputs!H124 -> 3 | M56: =J56/K56*L56*(1+Inputs!$F$86) -> 0
C57: Bioassays | E57: =IF(Inputs!$B$150=Inputs!$C$86,Inputs!C125,IF(Inputs!$B$150=Inputs!$G$86,Inputs!D125,IF(Inputs!$B$150=Inputs!$J$86,Inputs!E125,IF(Inputs!$B$150=Inputs!$M$86,Inputs!F125,"na")))) -> 0 | F57: /man/year | G57: 0.25 | H57: year | I57: =Inputs!F$166 -> 12 | J57: =I57*G57*E57 -> 0 | K57: 1 | L57: =Inputs!H125 -> 250 | M57: =J57/K57*L57*(1+Inputs!$F$86) -> 0
C58: (Bioassays for aver. crew & management) | M58: =SUM(M49:M57) -> 0
C60: Small Tools - 2% of total labor costs = | G60: =(T6-T8) -> 2717219.4 | H60: labor costs x | I60: =Inputs!F128 -> 0.02 | J60: = | K60: =I60*G60 -> 54344.387
...

Sheet Building B56
A1: B 56 DATA - Data highlighted in GREEN can be adjusted as needed
J2: Uncorrected Duration
I3: Crew | J3: (No. of Hours) | K3: Prod. Factor | L3: Adjusted Duration (hrs) | M3: Man-hours | N3: LSA Waste Disp. Vol (cm) | O3: Hazardous Waste Vol (cm) | Q3: Mixed Waste Volume (cm) | R3: Clean Waste Volume (cm) | S3: Materials, Consumables & Equipment | T3: Labor Cost | U3: LSA Waste Costs | V3: Hazardous Waste Costs | W3: LSA Waste Costs | X3: Mixed Waste Costs | Y3: Clean Waste Costs | Z3: Total Cost
A6: 1.0 | B6: Building B56 | L6: =L8+L66+L118+L177+L185+L207 -> 647 | M6: =M8+M66+M118+M177+M185+M207 -> 6605 | N6: =N8+N66+N118+N177+N185+N207 -> 39.256953 | O6: =O8+O66+O118+O177+O185+O207 -> 425.0234 | Q6: =Q8+Q66+Q118+Q177+Q185+Q207 -> 4.4867312 | R6: =R8+R66+R118+R177+R185+R207 -> 1734.4379 | S6: =S8+S66+S118+S177+S185+S207+S214 -> 1843800 | T6: =T8+T66+T118+T177+T185+T207+T214 -> 11009187 | V6: =V8+V66+V118+V177+V185+V207+V214 -> 375239.61 | X6: =X8+X66+X118+X177+X185+X207+X214 -> 3961.1919 | Y6: =Y8+Y66+Y118+Y177+Y185+Y207+Y214 -> 918767.96 | Z6: =SUM(S6:Y6) -> 14150956
A8: 1.1 | B8: Project Management | S8: =IF(G18="US",(H46+M58+K60+K62+K64)*Inputs!C37,(H46+M58+K60+K62+K64)) -> 1843800 | T8: =I15 -> 256232.55 | Z8: =SUM(S8:Y8) -> 2100032.5
A10: 1.1.1 | B10: Staff | E10: Number | F10: Rate | G10: Duration, days* | H10: Use Factor | I10: Cost | J10: Man-hours
B11: =Inputs!A$51 -> Portfolio Manager | E11: 1 | F11: =Inputs!E51 -> 157.87 | G11: =Inputs!G$209 -> 105 | H11: 1 | I11: =H11*G11*F11*E11*8 -> 132610.8 | J11: =H11*G11*10 -> 1050
B12: =Inputs!A$50 -> Senior Project Manager / Characterization SME | E12: 1 | F12: =Inputs!E50 -> 127.28 | G12: =Inputs!G$209 -> 105 | H12: 0.5 | I12: =H12*G12*F12*E12*10 -> 66822 | J12: =H12*G12*10 -> 525
B13: =Inputs!A$49 -> Project Manager / Waste Management | E13: 1 | F13: =Inputs!E49 -> 108.19 | G13: =Inputs!G$209 -> 105 | H13: 0.5 | I13: =H13*G13*F13*E13*10 -> 56799.75 | J13: =H13*G13*10 -> 525
B14: =Inputs!A$48 -> Decom Technician / Safety SME | E14: 0 | F14: =Inputs!E48 -> 89.25 | G14: =Inputs!G$209 -> 105 | H14: 1 | I14: =H14*G14*F14*E14*10 -> 0 | J14: =H14*G14*10 -> 1050
E15: =SUM(E11:E14) -> 3 | I15: =SUM(I11:I14) -> 256232.55 | J15: =SUM(J11:J14) -> 3150
A17: 1.1.2 | B17: Equipment & Materials
G18: =Inputs!D85 -> US
C19: Equipment | F19: Quantity | G19: Rate | H19: Escalated Cost
C20: HEPA filter systems | F20: =IF(Inputs!$B$206=Inputs!$C$86,Inputs!C88,IF(Inputs!$B$206=Inputs!$G$86,Inputs!G88,IF(Inputs!$B$206=Inputs!$J$86,Inputs!J88,IF(Inputs!$B$206=Inputs!$M$86,Inputs!M88,"na")))) -> 2 | G20: =Inputs!D88 -> 3598.14 | H20: =G20*F20*(1+Inputs!$F$86) -> 11371.124
C21: Replacement filters | F21: =IF(Inputs!$B$206=Inputs!$C$86,Inputs!C89,IF(Inputs!$B$206=Inputs!$G$86,Inputs!G89,IF(Inputs!$B$206=Inputs!$J$86,Inputs!J89,IF(Inputs!$B$206=Inputs!$M$86,Inputs!M89,"na")))) -> 24 | G21: =Inputs!D89 -> 581.07 | H21: =G21*F21*(1+Inputs!$F$86) -> 22036.115
C22: Respirator | F22: =IF(Inputs!$B$206=Inputs!$C$86,Inputs!C90,IF(Inputs!$B$206=Inputs!$G$86,Inputs!G90,IF(Inputs!$B$206=Inputs!$J$86,Inputs!J90,IF(Inputs!$B$206=Inputs!$M$86,Inputs!M90,"na")))) -> 12 | G22: =Inputs!D90 -> 259 | H22: =G22*F22*(1+Inputs!$F$86) -> 4911.0725
C23: Rad/Vac wet-dry high eff. vacuum | F23: =IF(Inputs!$B$206=Inputs!$C$86,Inputs!C91,IF(Inputs!$B$206=Inputs!$G$86,Inputs!G91,IF(Inputs!$B$206=Inputs!$J$86,Inputs!J91,IF(Inputs!$B$206=Inputs!$M$86,Inputs!M91,"na")))) -> 1 | G23: =Inputs!D91 -> 3879 | H23: =G23*F23*(1+Inputs!$F$86) -> 6129.3598
C24: Rad/Vac wet-dry high eff. vacuum filters | F24: =IF(Inputs!$B$206=Inputs!$C$86,Inputs!C92,IF(Inputs!$B$206=Inputs!$G$86,Inputs!G92,IF(Inputs!$B$206=Inputs!$J$86,Inputs!J92,IF(Inputs!$B$206=Inputs!$M$86,Inputs!M92,"na")))) -> 5 | G24: =Inputs!D92 -> 412 | H24: =G24*F24*(1+Inputs!$F$86) -> 3255.0867
C25: Reciprocating Saws | F25: =IF(Inputs!$B$206=Inputs!$C$86,Inputs!C93,IF(Inputs!$B$206=Inputs!$G$86,Inputs!G93,IF(Inputs!$B$206=Inputs!$J$86,Inputs!J93,IF(Inputs!$B$206=Inputs!$M$86,Inputs!M93,"na")))) -> 5 | G25: =Inputs!D93 -> 1252.26 | H25: =G25*F25*(1+Inputs!$F$86) -> 9893.7254
C26: Pneumatic chipping hammers | F26: =IF(Inputs!$B$206=Inputs!$C$86,Inputs!C94,IF(Inputs!$B$206=Inputs!$G$86,Inputs!G94,IF(Inputs!$B$206=Inputs!$J$86,Inputs!J94,IF(Inputs!$B$206=Inputs!$M$86,Inputs!M94,"na")))) -> 2 | G26: =Inputs!D94 -> 1606.71 | H26: =G26*F26*(1+Inputs!$F$86) -> 5077.6508
C27: Chipping hammer blades | F27: =IF(Inputs!$B$206=Inputs!$C$86,Inputs!C95,IF(Inputs!$B$206=Inputs!$G$86,Inputs!G95,IF(Inputs!$B$206=Inputs!$J$86,Inputs!J95,IF(Inputs!$B$206=Inputs!$M$86,Inputs!M95,"na")))) -> 20 | G27: =Inputs!D95 -> 27.42 | H27: =G27*F27*(1+Inputs!$F$86) -> 866.54832
C28: Purchase an air compressor: | F28: =IF(Inputs!$B$206=Inputs!$C$86,Inputs!C96,IF(Inputs!$B$206=Inputs!$G$86,Inputs!G96,IF(Inputs!$B$206=Inputs!$J$86,Inputs!J96,IF(Inputs!$B$206=Inputs!$M$86,Inputs!M96,"na")))) -> 2 | G28: =Inputs!D96 -> 1723.44 | H28: =G28*F28*(1+Inputs!$F$86) -> 5446.5501
C29: Jackhammer | F29: =IF(Inputs!$B$206=Inputs!$C$86,Inputs!C97,IF(Inputs!$B$206=Inputs!$G$86,Inputs!G97,IF(Inputs!$B$206=Inputs!$J$86,Inputs!J97,IF(Inputs!$B$206=Inputs!$M$86,Inputs!M97,"na")))) -> 4 | G29: =Inputs!D97 -> 1417.11 | H29: =G29*F29*(1+Inputs!$F$86) -> 8956.9241
C30: Jackhammer Chisels | F30: =IF(Inputs!$B$206=Inputs!$C$86,Inputs!C98,IF(Inputs!$B$206=Inputs!$G$86,Inputs!G98,IF(Inputs!$B$206=Inputs!$J$86,Inputs!J98,IF(Inputs!$B$206=Inputs!$M$86,Inputs!M98,"na")))) -> 10 | G30: =Inputs!D98 -> 24.35 | H30: =G30*F30*(1+Inputs!$F$86) -> 384.76389
C31: Safety glasses | F31: =IF(Inputs!$B$206=Inputs!$C$86,Inputs!C99,IF(Inputs!$B$206=Inputs!$G$86,Inputs!G99,IF(Inputs!$B$206=Inputs!$J$86,Inputs!J99,IF(Inputs!$B$206=Inputs!$M$86,Inputs!M99,"na")))) -> 15 | G31: =Inputs!D99 -> 8.6 | H31: =G31*F31*(1+Inputs!$F$86) -> 203.83795
... C45: Crane rental for building removal | F45: =IF(Inputs!$B$206=Inputs!$C$86,Inputs!C113,IF(Inputs!$B$206=Inputs!$G$86,Inputs!G113,IF(Inputs!$B$206=Inputs!$J$86,Inputs!J113,IF(Inputs!$B$206=Inputs!$M$86,Inputs!M113,"na")))) -> 1 | G45: =Inputs!D113 -> 15600 | H45: =G45*F45*(1+Inputs!$F$86) -> 24650.171
H46: =SUM(H20:H45) -> 226414.4
C48: Consumables | E48: Quantity | G48: Duration | I48: # workers | J48: quantity | K48: Unit Qty | L48: Unit Cost | M48: Escalated Cost
C49: Coveralls | E49: =IF(Inputs!$B$206=Inputs!$C$86,Inputs!C117,IF(Inputs!$B$206=Inputs!$G$86,Inputs!D117,IF(Inputs!$B$206=Inputs!$J$86,Inputs!E117,IF(Inputs!$B$206=Inputs!$M$86,Inputs!F117,"na")))) -> 2 | F49: /man/day | G49: =Inputs!G$209 -> 105 | H49: days | I49: =Inputs!H$212 -> 24 | J49: =I49*G49*E49 -> 5040 | K49: 1 | L49: =Inputs!H117 -> 11 | M49: =J49/K49*L49*(1+Inputs!$F$86) -> 87602.916
C50: Hoods | E50: =IF(Inputs!$B$206=Inputs!$C$86,Inputs!C118,IF(Inputs!$B$206=Inputs!$G$86,Inputs!D118,IF(Inputs!$B$206=Inputs!$J$86,Inputs!E118,IF(Inputs!$B$206=Inputs!$M$86,Inputs!F118,"na")))) -> 0.1 | F50: /man/day | G50: =Inputs!G$209 -> 105 | H50: days | I50: =Inputs!H$212 -> 24 | J50: =I50*G50*E50 -> 252 | K50: 1 | L50: =Inputs!H118 -> 0 | M50: =J50/K50*L50*(1+Inputs!$F$86) -> 0
C51: Shoe covers | E51: =IF(Inputs!$B$206=Inputs!$C$86,Inputs!C119,IF(Inputs!$B$206=Inputs!$G$86,Inputs!D119,IF(Inputs!$B$206=Inputs!$J$86,Inputs!E119,IF(Inputs!$B$206=Inputs!$M$86,Inputs!F119,"na")))) -> 4 | F51: /man/day | G51: =Inputs!G$209 -> 105 | H51: days | I51: =Inputs!H$212 -> 24 | J51: =I51*G51*E51 -> 10080 | K51: 1 | L51: =Inputs!H119 -> 0.94 | M51: =J51/K51*L51*(1+Inputs!$F$86) -> 14972.135
C52: Latex gloves | E52: =IF(Inputs!$B$206=Inputs!$C$86,Inputs!C120,IF(Inputs!$B$206=Inputs!$G$86,Inputs!D120,IF(Inputs!$B$206=Inputs!$J$86,Inputs!E120,IF(Inputs!$B$206=Inputs!$M$86,Inputs!F120,"na")))) -> 4 | F52: /man/day | G52: =Inputs!G$209 -> 105 | H52: days | I52: =Inputs!H$212 -> 24 | J52: =I52*G52*E52 -> 10080 | K52: 1 | L52: =Inputs!H120 -> 0.94 | M52: =J52/K52*L52*(1+Inputs!$F$86) -> 14972.135
C53: Rubber overshoes | E53: =IF(Inputs!$B$206=Inputs!$C$86,Inputs!C121,IF(Inputs!$B$206=Inputs!$G$86,Inputs!D121,IF(Inputs!$B$206=Inputs!$J$86,Inputs!E121,IF(Inputs!$B$206=Inputs!$M$86,Inputs!F121,"na")))) -> 0.01 | F53: /man/day | G53: =Inputs!G$209 -> 105 | H53: days | I53: =Inputs!H$212 -> 24 | J53: =I53*G53*E53 -> 25.2 | K53: 1 | L53: =Inputs!H121 -> 3 | M53: =J53/K53*L53*(1+Inputs!$F$86) -> 119.45852
C54: Gloves | E54: =IF(Inputs!$B$206=Inputs!$C$86,Inputs!C122,IF(Inputs!$B$206=Inputs!$G$86,Inputs!D122,IF(Inputs!$B$206=Inputs!$J$86,Inputs!E122,IF(Inputs!$B$206=Inputs!$M$86,Inputs!F122,"na")))) -> 0.01 | F54: /man/day | G54: =Inputs!G$209 -> 105 | H54: days | I54: =Inputs!H$212 -> 24 | J54: =I54*G54*E54 -> 25.2 | K54: 1 | L54: =Inputs!H122 -> 2 | M54: =J54/K54*L54*(1+Inputs!$F$86) -> 79.639014
C55: Dosimeters | E55: =IF(Inputs!$B$206=Inputs!$C$86,Inputs!C123,IF(Inputs!$B$206=Inputs!$G$86,Inputs!D123,IF(Inputs!$B$206=Inputs!$J$86,Inputs!E123,IF(Inputs!$B$206=Inputs!$M$86,Inputs!F123,"na")))) -> 1 | F55: /man/year | G55: 0.25 | H55: year | I55: =Inputs!H$212 -> 24 | J55: =I55*G55*E55 -> 6 | K55: 1 | L55: =Inputs!H123 -> 200 | M55: =J55/K55*L55*(1+Inputs!$F$86) -> 1896.167
